<?xml version="1.0"?>
<robot name="create">
    <link name="base_footprint">
        <visual name="base_visual">
            <origin xyz="0 0 0.047800" rpy="0 0 0 " />
            <geometry>
                <mesh filename="meshes/create_body.dae"/>
            </geometry>
        </visual>
    </link>
    <link name="us1_link"/>
    <link name="us2_link"/>
    <link name="us3_link"/>
    <link name="us4_link"/>
    <link name="us5_link"/>
    <link name="us6_link"/>
    <link name="us7_link"/>
    <link name="us8_link"/>
    <link name="imu_link"/>
    <link name="left_wheel_link">
        <visual>
            <geometry>
                <cylinder length="0.023000" radius="0.033000"/>
            </geometry>
        </visual>
    </link>
    <link name="right_wheel_link">
        <visual>
            <geometry>
                <cylinder length="0.023000" radius="0.033000"/>
            </geometry>
        </visual>
    </link>
    <joint name="base_us1_joint" type="fixed">
        <parent link="base_footprint"/>
        <child link="us1_link"/>
        <origin xyz="0.13 0.11 0.07" rpy="0 0 1.5708" />
    </joint>
    <joint name="base_us2_joint" type="fixed">
        <parent link="base_footprint"/>
        <child link="us2_link"/>
        <origin xyz="0.11 0.13 0.07" rpy="0 0 0" />
    </joint>
    <joint name="base_us3_joint" type="fixed">
        <parent link="base_footprint"/>
        <child link="us3_link"/>
        <origin xyz="0.11 -0.13 0.07" rpy="0 0 0" />
    </joint>
    <joint name="base_us4_joint" type="fixed">
        <parent link="base_footprint"/>
        <child link="us4_link"/>
        <origin xyz="0.13 -0.11 0.07" rpy="0 0 -1.5708" />
    </joint>
    <joint name="base_us5_joint" type="fixed">
        <parent link="base_footprint"/>
        <child link="us5_link"/>
        <origin xyz="-0.13 -0.11 0.07" rpy="0 0 -1.5708" />
    </joint>
    <joint name="base_us6_joint" type="fixed">
        <parent link="base_footprint"/>
        <child link="us6_link"/>
        <origin xyz="-0.11 -0.13 0.07" rpy="0 0 3.14" />
    </joint>
    <joint name="base_us7_joint" type="fixed">
        <parent link="base_footprint"/>
        <child link="us7_link"/>
        <origin xyz="-0.11 0.13 0.07" rpy="0 0 3.14" />
    </joint>
    <joint name="base_us8_joint" type="fixed">
        <parent link="base_footprint"/>
        <child link="us8_link"/>
        <origin xyz="-0.13 0.11 0.07" rpy="0 0 1.5708" />
    </joint>
    <joint name="base_imu_joint" type="fixed">
        <parent link="base_footprint"/>
        <child link="imu_link"/>
        <origin xyz="0 0 0" rpy="0 0 0" />
    </joint>
    <joint name="left_wheel" type="continuous">
        <parent link="base_footprint"/>
        <child link="left_wheel_link"/>
        <origin xyz="0 0.130000 0.032000" rpy="0 1.5708 1.5708" />
        <axis xyz="0 0 1"/>
    </joint>
    <joint name="right_wheel" type="continuous">
        <parent link="base_footprint"/>
        <child link="right_wheel_link"/>
        <origin xyz="0 -0.130000 0.032000" rpy="0 1.5708 1.5708" />
        <axis xyz="0 0 1"/>
    </joint>
</robot>