<?xml version="1.0" ?>
<!-- =================================================================================== -->
<!-- |    This document was autogenerated by xacro from iRobot.urdf.xacro              | -->
<!-- |    EDITING THIS FILE BY HAND IS NOT RECOMMENDED                                 | -->
<!-- =================================================================================== -->
<robot name="iRobot">

    <material name="black"> 
        <color rgba="0 0 0 1"/>
    </material>
    <material name="blue"> 
        <color rgba="0.0 0.0 0.8 1"/>
    </material>
      <material name="red">
    <color rgba="0.8 0.0 0.0 1"/>
  </material>
<material name="grey">
    <color rgba="0.4 0.4 0.4 1.0"/>
  </material>

  <material name="yellow">
    <color rgba="1.0, 1.0, 0.0, 1.0"/>
  </material>


    <link name="base_footprint">
        <visual name="base_visual">
            <origin xyz="0 0 0.047800" rpy="0 0 0 " />
            <geometry>
                <mesh filename="meshes/create_body3.dae"/>
            </geometry>
            <material name="grey"/>
        </visual>

        <collision name="base_visual">
            <origin xyz="0 0 0.047800" rpy="0 0 0 " />
            <geometry>
                <mesh filename="meshes/create_body3.dae"/>
            </geometry>
        </collision>

        <inertial>
            <origin  xyz="0.001453 -0.000453 0.029787" rpy="0 0 0"/>
            <mass value="5.234000"/>
            <inertia ixx="0.0000" ixy="0.00000" ixz="0.000" iyy="0.000" iyz="0.000000" izz="0"/>
        </inertial>

    </link>

    <!-- Left  Wheel -->
    <link name="left_wheel_link">
        <visual>
            <geometry>
                <cylinder length="0.023000" radius="0.03000"/>
            </geometry>
            <material name="blue"/>
        </visual>

        <collision>
            <geometry>
                <cylinder length="0.023000" radius="0.03000"/>
            </geometry>
        </collision>

        <inertial>
            <origin xyz="0 0 -0.0225"  rpy="0 0 0"/>
            <mass value="0.34055"/>
            <inertia ixx="0.00026046" ixy="0" ixz="0" iyy="0.00026046" iyz="0" izz="0.00041226"/>
        </inertial>
    </link>

    <joint name="left_wheel" type="continuous">
        <parent link="base_footprint"/>
        <child link="left_wheel_link"/>
        <origin xyz="0 0.130000 0.033000" rpy="0 1.5708 1.5708" />
        <axis xyz="0 0 1"/>
    </joint>


    <!-- Right  Wheel -->
    <link name="right_wheel_link">
        <visual>
            <geometry>
                <cylinder length="0.023000" radius="0.03000"/>
            </geometry>
            <material name="red"/>
        </visual>

        <collision>
            <geometry>
                <cylinder length="0.023000" radius="0.03000"/>
            </geometry>
        </collision>

        <inertial>
            <origin xyz="0 0 -0.0225"  rpy="0 0 0"/>
            <mass value="0.34055"/>
            <inertia ixx="0.00026046" ixy="0" ixz="0" iyy="0.00026046" iyz="0" izz="0.00041226"/>
        </inertial>
    </link>

    <joint name="right_wheel" type="continuous">
        <parent link="base_footprint"/>
        <child link="right_wheel_link"/>
        <origin xyz="0 -0.130000 0.033000" rpy="0 1.5708 1.5708" />
        <axis xyz="0 0 1"/>
    </joint>


    <!-- front  Wheel -->
    <link name="front_wheel_link">
        <visual>
            <geometry>
                <sphere radius="0.015" />
            </geometry>
            <material name="black"/>
        </visual>
        <collision>
            <geometry>
                <sphere radius="0.013" />
            </geometry>
        </collision>
        <inertial>
            <origin  xyz="0 0 0" rpy="0 0 0"/>
            <mass value="0.005"/>
            <inertia ixx="0." ixy="0." ixz="0." iyy="0." iyz="0." izz="0."/>
        </inertial>
    </link>

    <joint name="front_wheel" type="continuous">
        <parent link="base_footprint"/>
        <child link="front_wheel_link"/>
        <origin xyz="0.130000 0 0.016000" rpy="0 0 0" />
        <axis xyz="0 0 1"/>
    </joint>

    <!-- rear  Wheel -->
    <link name="rear_wheel_link">
        <visual>
            <geometry>
                <sphere radius="0.009" />
            </geometry>
            <material name="black"/>
        </visual>
        <collision>
            <geometry>
                <sphere radius="0.01000" />
            </geometry>
        </collision>
        <inertial>
            <origin  xyz="0 0 0" rpy="0 0 0"/>
            <mass value="0.005"/>
            <inertia ixx="0." ixy="0." ixz="0." iyy="0." iyz="0." izz="0."/>
        </inertial>
    </link>

    <joint name="rear_wheel" type="continuous">
        <parent link="base_footprint"/>
        <child link="rear_wheel_link"/>
        <origin xyz="-0.130000 0 0.016000" rpy="0 0 0" />
        <axis xyz="0 0 1"/>
    </joint>


  <link name="laser">
    <inertial>
      <origin rpy="0 0 0" xyz="0 0 0"/>
      <mass value="0.0"/>
      <inertia ixx="4E-06" ixy="0" ixz="0" iyy="0" iyz="0" izz="0"/>
    </inertial>
    <collision>
      <origin rpy="0 0 0" xyz="0 0 0"/>
      <geometry>
        <mesh scale="0.5 0.5 0.5 0.5" filename="meshes/hokuyo.obj"/>
      </geometry>
    </collision>
    <visual>
      <origin rpy="0 0 0" xyz="0 0 0"/>
      <geometry>
        <mesh scale="0.5 0.5 0.5 0.5" filename="meshes/hokuyo.obj"/>
      </geometry>
        <material name="yellow"/>

    </visual>
  </link>

  <joint name="hokuyo_joint" type="fixed">
    <origin rpy="0 0 0" xyz="0 0.0 0.085"/>
    <parent link="base_footprint"/>
    <child link="laser"/>
    <axis xyz="0 0 1"/>
  </joint>


</robot>
