<?xml version="1.0"?>
<robot name="MyRobot">

<link name="base_link">
   <visual>
    <geometry>
     <cylinder length="0.035" radius="0.05"/>
    </geometry>
      <material name="blue"> 
        <color rgba="0 0 0.8 1"/>
    </material>
   </visual>

 </link>

 <link name="right_wheel"> 
    <visual> 
      <geometry> 
        <cylinder length="0.005" radius="0.016"/> 
      </geometry> 
      <material name="white">
        <color rgba="1 1 1 1"/>
      </material> 
    </visual> 


  </link>
<joint name="right_wheel_joint" type="continuous"> 
    <axis xyz="0 0 1"/> 
    <parent link="base_link"/> 
    <child link="right_wheel"/> 
    <origin rpy="0 -1.5708 0" xyz="0.05 0 -0.0105"/> 
  </joint>

   <link name="left_wheel"> 
    <visual> 
      <geometry> 
        <cylinder length="0.005" radius="0.016"/> 
      </geometry> 
      <material name="white">
        <color rgba="1 1 1 1"/>
      </material> 
    </visual> 

  </link>

    <joint name="left_wheel_joint" type="continuous"> 
    <axis xyz="0 0 1"/> 
    <parent link="base_link"/> 
    <child link="left_wheel"/> 
    <origin rpy="0 -1.5708 0" xyz="-0.05 0 -0.0105"/> 
  </joint>


</robot>