<?xml version="1.0" ?>
<sdf version="1.4">
  <model name="create">


    <!-- funkcny sposob senzorov priestoru je dat tie senzory
    priamo do "base" liku. Vyriesi to problem s neprichytenim
    a nepublikovanim -->

    <link name="odom"></link>
    <joint name="odom_base_joint" type="fixed">
      <parent>odom</parent>
      <child>base_footprint</child>
    </joint>

    <link name="base_footprint">
      <inertial>
        <pose>0.001453 -0.000453 0.029787 0 0 0</pose>
        <inertia>
          <ixx>0.058640</ixx>
          <ixy>0.000124</ixy>
          <ixz>0.000615</ixz>
          <iyy>0.058786</iyy>
          <iyz>0.000014</iyz>
          <izz>1.532440</izz>
        </inertia>
        <mass>2.234000</mass>
      </inertial>

      <collision name="base_collision">
        <pose>0 0 0.047800 0 0 0</pose>
        <geometry>
          <cylinder>
            <radius>0.016495</radius>
            <length>0.061163</length>
          </cylinder>
        </geometry>
      </collision>
      <visual name="base_visual">
        <pose>0 0 0.047800 0 0 0</pose>
        <geometry>
          <mesh>
            <uri>model://create/meshes/create_body.dae</uri>
          </mesh>
        </geometry>
      </visual>

      <collision name="front_wheel_collision">
        <pose>0.130000 0 0.017000 0 1.570700 1.570700</pose>
        <geometry>
          <sphere>
            <radius>0.018000</radius>
          </sphere>
        </geometry>
        <surface>
          <friction>
            <ode>
              <mu>0</mu>
              <mu2>0</mu2>
              <fdir1>0 0 0</fdir1>
              <slip1>0</slip1>
              <slip2>0</slip2>
            </ode>
          </friction>
        </surface>
      </collision>
      <visual name="front_wheel_visual">
        <pose>0.130000 0 0.017000 0 1.570700 1.570700</pose>
        <geometry>
          <sphere>
            <radius>0.009000</radius>
          </sphere>
        </geometry>
      </visual>

      <collision name="rear_wheel_collision">
        <pose>-0.13 0 0.017 0 1.5707 1.5707</pose>
        <geometry>
          <sphere>
            <radius>0.015000</radius>
          </sphere>
        </geometry>
        <surface>
          <friction>
            <ode>
              <mu>0</mu>
              <mu2>0</mu2>
              <fdir1>0 0 0</fdir1>
              <slip1>0</slip1>
              <slip2>0</slip2>
            </ode>
          </friction>
        </surface>
      </collision>
      <visual name="rear_wheel_visual">
        <pose>-0.130000 0 0.017000 0 1.570700 1.570700</pose>
        <geometry>
          <sphere>
            <radius>0.007500</radius>
          </sphere>
        </geometry>
      </visual>

      <!-- moje senzory sensors_read -->
      <!-- sensors_read 1 -->
      <sensor name="ultrasonic1" type="ray">
        <pose>0.13 0.11 0.07 0 0 1.5708</pose>
        <ray>
          <scan>
            <horizontal>
              <samples>20</samples>
              <resolution>1</resolution>
              <min_angle>-0.1</min_angle>
              <max_angle>0.1</max_angle>
            </horizontal>
          </scan>
          <range>
            <min>0.02</min>
            <max>1</max>
            <resolution>0.005</resolution>
          </range>
          <noise>
            <type>gaussian</type>
            <mean>0.0</mean>
            <stddev>0.01</stddev>
          </noise>
        </ray>

        <plugin name="laser" filename="libgazebo_ros_laser.so">
          <gaussianNoise>0.005</gaussianNoise>
          <topicName>ultrasonic1</topicName>
          <frameName>us1_link</frameName>
        </plugin>
        <always_on>1</always_on>
        <update_rate>30</update_rate>
        <visualize>true</visualize>
      </sensor>

      <!-- sensors_read 2 -->
      <sensor name="ultrasonic2" type="ray">
        <pose>0.11 0.13 0.07 0 0 0</pose>
        <ray>
          <scan>
            <horizontal>
              <samples>20</samples>
              <resolution>1</resolution>
              <min_angle>-0.1</min_angle>
              <max_angle>0.1</max_angle>
            </horizontal>
          </scan>
          <range>
            <min>0.02</min>
            <max>1</max>
            <resolution>0.005</resolution>
          </range>
          <noise>
            <type>gaussian</type>
            <mean>0.0</mean>
            <stddev>0.01</stddev>
          </noise>
        </ray>

        <plugin name="laser" filename="libgazebo_ros_laser.so">
          <gaussianNoise>0.005</gaussianNoise>
          <topicName>ultrasonic2</topicName>
          <frameName>us2_link</frameName>
        </plugin>
        <always_on>1</always_on>
        <update_rate>30</update_rate>
        <visualize>true</visualize>
      </sensor>

      <!-- sensors_read 3 -->
      <sensor name="ultrasonic3" type="ray">
        <pose>0.11 -0.13 0.07 0 0 0</pose>
        <ray>
          <scan>
            <horizontal>
              <samples>20</samples>
              <resolution>1</resolution>
              <min_angle>-0.1</min_angle>
              <max_angle>0.1</max_angle>
            </horizontal>
          </scan>
          <range>
            <min>0.02</min>
            <max>1</max>
            <resolution>0.005</resolution>
          </range>
          <noise>
            <type>gaussian</type>
            <mean>0.0</mean>
            <stddev>0.01</stddev>
          </noise>
        </ray>

        <plugin name="laser" filename="libgazebo_ros_laser.so">
          <gaussianNoise>0.005</gaussianNoise>
          <topicName>ultrasonic3</topicName>
          <frameName>us3_link</frameName>
        </plugin>
        <always_on>1</always_on>
        <update_rate>30</update_rate>
        <visualize>true</visualize>
      </sensor>

      <!-- sensors_read 4 -->
      <sensor name="ultrasonic4" type="ray">
        <pose>0.13 -0.11 0.07 0 0 -1.5708</pose>
        <ray>
          <scan>
            <horizontal>
              <samples>20</samples>
              <resolution>1</resolution>
              <min_angle>-0.1</min_angle>
              <max_angle>0.1</max_angle>
            </horizontal>
          </scan>
          <range>
            <min>0.02</min>
            <max>1</max>
            <resolution>0.005</resolution>
          </range>
          <noise>
            <type>gaussian</type>
            <mean>0.0</mean>
            <stddev>0.01</stddev>
          </noise>
        </ray>

        <plugin name="laser" filename="libgazebo_ros_laser.so">
          <gaussianNoise>0.005</gaussianNoise>
          <topicName>ultrasonic4</topicName>
          <frameName>us4_link</frameName>
        </plugin>
        <always_on>1</always_on>
        <update_rate>30</update_rate>
        <visualize>true</visualize>
      </sensor>

      <!-- sensors_read 5 -->
      <sensor name="ultrasonic5" type="ray">
        <pose>-0.13 -0.11 0.07 0 0 -1.5708</pose>
        <ray>
          <scan>
            <horizontal>
              <samples>20</samples>
              <resolution>1</resolution>
              <min_angle>-0.1</min_angle>
              <max_angle>0.1</max_angle>
            </horizontal>
          </scan>
          <range>
            <min>0.02</min>
            <max>1</max>
            <resolution>0.005</resolution>
          </range>
          <noise>
            <type>gaussian</type>
            <mean>0.0</mean>
            <stddev>0.01</stddev>
          </noise>
        </ray>

        <plugin name="laser" filename="libgazebo_ros_laser.so">
          <gaussianNoise>0.005</gaussianNoise>
          <topicName>ultrasonic5</topicName>
          <frameName>us5_link</frameName>
        </plugin>
        <always_on>1</always_on>
        <update_rate>30</update_rate>
        <visualize>true</visualize>
      </sensor>

      <!-- sensors_read 6 -->
      <sensor name="ultrasonic6" type="ray">
        <pose>-0.11 -0.13 0.07 0 0 3.14</pose>
        <ray>
          <scan>
            <horizontal>
              <samples>20</samples>
              <resolution>1</resolution>
              <min_angle>-0.1</min_angle>
              <max_angle>0.1</max_angle>
            </horizontal>
          </scan>
          <range>
            <min>0.02</min>
            <max>1</max>
            <resolution>0.005</resolution>
          </range>
          <noise>
            <type>gaussian</type>
            <mean>0.0</mean>
            <stddev>0.01</stddev>
          </noise>
        </ray>

        <plugin name="laser" filename="libgazebo_ros_laser.so">
          <gaussianNoise>0.005</gaussianNoise>
          <topicName>ultrasonic6</topicName>
          <frameName>us6_link</frameName>
        </plugin>
        <always_on>1</always_on>
        <update_rate>30</update_rate>
        <visualize>true</visualize>
      </sensor>

      <!-- sensors_read 7 -->
      <sensor name="ultrasonic7" type="ray">
        <pose>-0.11 0.13 0.07 0 0 3.14</pose>
        <ray>
          <scan>
            <horizontal>
              <samples>20</samples>
              <resolution>1</resolution>
              <min_angle>-0.1</min_angle>
              <max_angle>0.1</max_angle>
            </horizontal>
          </scan>
          <range>
            <min>0.02</min>
            <max>1</max>
            <resolution>0.005</resolution>
          </range>
          <noise>
            <type>gaussian</type>
            <mean>0.0</mean>
            <stddev>0.01</stddev>
          </noise>
        </ray>

        <plugin name="laser" filename="libgazebo_ros_laser.so">
          <gaussianNoise>0.005</gaussianNoise>
          <topicName>ultrasonic7</topicName>
          <frameName>us7_link</frameName>
        </plugin>
        <always_on>1</always_on>
        <update_rate>30</update_rate>
        <visualize>true</visualize>
      </sensor>

      <!-- sensors_read 8 -->
      <sensor name="ultrasonic8" type="ray">
        <pose>-0.13 0.11 0.07 0 0 1.5708</pose>
        <ray>
          <scan>
            <horizontal>
              <samples>20</samples>
              <resolution>1</resolution>
              <min_angle>-0.1</min_angle>
              <max_angle>0.1</max_angle>
            </horizontal>
          </scan>
          <range>
            <min>0.02</min>
            <max>1</max>
            <resolution>0.005</resolution>
          </range>
          <noise>
            <type>gaussian</type>
            <mean>0.0</mean>
            <stddev>0.01</stddev>
          </noise>
        </ray>

        <plugin name="laser" filename="libgazebo_ros_laser.so">
          <gaussianNoise>0.005</gaussianNoise>
          <topicName>ultrasonic8</topicName>
          <frameName>us8_link</frameName>
        </plugin>
        <always_on>1</always_on>
        <update_rate>30</update_rate>
        <visualize>true</visualize>
      </sensor>






      <sensor name="left_cliff_sensor" type="ray">
        <pose>0.070000 0.140000 0.027000 0 1.570790 0</pose>
        <ray>
          <scan>
            <horizontal>
              <samples>1</samples>
              <resolution>1.000000</resolution>
              <min_angle>0</min_angle>
              <max_angle>0</max_angle>
            </horizontal>
          </scan>
          <range>
            <min>0.010000</min>
            <max>0.040000</max>
            <resolution>0.100000</resolution>
          </range>
        </ray>
      </sensor>

      <sensor name="leftfront_cliff_sensor" type="ray">
        <pose>0.150000 0.040000 0.027000 0 1.570790 0</pose>
        <ray>
          <scan>
            <horizontal>
              <samples>1</samples>
              <resolution>1.000000</resolution>
              <min_angle>0</min_angle>
              <max_angle>0</max_angle>
            </horizontal>
          </scan>
          <range>
            <min>0.010000</min>
            <max>0.040000</max>
            <resolution>0.100000</resolution>
          </range>
        </ray>
      </sensor>

      <sensor name="right_cliff_sensor" type="ray">
        <pose>0.070000 -0.140000 0.027000 0 1.570790 0</pose>
        <ray>
          <scan>
            <horizontal>
              <samples>1</samples>
              <resolution>1.000000</resolution>
              <min_angle>0</min_angle>
              <max_angle>0</max_angle>
            </horizontal>
          </scan>
          <range>
            <min>0.010000</min>
            <max>0.040000</max>
            <resolution>0.100000</resolution>
          </range>
        </ray>
      </sensor>

      <sensor name="rightfront_cliff_sensor" type="ray">
        <pose>0.150000 -0.040000 0.027000 0 1.570790 0</pose>
        <ray>
          <scan>
            <horizontal>
              <samples>1</samples>
              <resolution>1.000000</resolution>
              <min_angle>0</min_angle>
              <max_angle>0</max_angle>
            </horizontal>
          </scan>
          <range>
            <min>0.010000</min>
            <max>0.040000</max>
            <resolution>0.100000</resolution>
          </range>
        </ray>
      </sensor>

      <sensor name="wall_sensor" type="ray">
        <pose>0.090000 -0.120000 0.059000 0 0 -1.000000</pose>
        <ray>
          <scan>
            <horizontal>
              <samples>1</samples>
              <resolution>1.000000</resolution>
              <min_angle>0</min_angle>
              <max_angle>0</max_angle>
            </horizontal>
          </scan>
          <range>
            <min>0.016000</min>
            <max>0.040000</max>
            <resolution>0.100000</resolution>
          </range>
        </ray>
      </sensor>
    </link>


    <link name="left_wheel">
      <pose>0 0.130000 0.032000 0 0 0</pose>
      <inertial>
        <inertia>
          <ixx>0.001000</ixx>
          <ixy>0</ixy>
          <ixz>0</ixz>
          <iyy>0.001000</iyy>
          <iyz>0</iyz>
          <izz>0.001000</izz>
        </inertia>
        <mass>0.010000</mass>
      </inertial>
      <collision name="collision">
        <pose>0 0 0 0 1.570700 1.570700</pose>
        <geometry>
          <cylinder>
            <radius>0.033000</radius>
            <length>0.023000</length>
          </cylinder>
        </geometry>
        <surface>
          <friction>
            <ode>
              <mu>10</mu>
              <mu2>10</mu2>
              <fdir1>0 0 0</fdir1>
              <slip1>0</slip1>
              <slip2>0</slip2>
            </ode>
          </friction>
        </surface>
      </collision>
      <visual name="visual">
        <pose>0 0 0 0 1.570700 1.570700</pose>
        <geometry>
          <cylinder>
            <radius>0.033000</radius>
            <length>0.023000</length>
          </cylinder>
        </geometry>
      </visual>
    </link>

    <link name="right_wheel">
      <pose>0 -0.130000 0.032000 0 0 0</pose>
      <inertial>
        <inertia>
          <ixx>0.001000</ixx>
          <ixy>0</ixy>
          <ixz>0</ixz>
          <iyy>0.001000</iyy>
          <iyz>0</iyz>
          <izz>0.001000</izz>
        </inertia>
        <mass>0.010000</mass>
      </inertial>
      <collision name="collision">
        <pose>0 0 0 0 1.570700 1.570700</pose>
        <geometry>
          <cylinder>
            <radius>0.033000</radius>
            <length>0.023000</length>
          </cylinder>
        </geometry>
        <surface>
          <friction>
            <ode>
              <mu>10</mu>
              <mu2>10</mu2>
              <fdir1>0 0 0</fdir1>
              <slip1>0</slip1>
              <slip2>0</slip2>
            </ode>
          </friction>
        </surface>
      </collision>
      <visual name="visual">
        <pose>0 0 0 0 1.570700 1.570700</pose>
        <geometry>
          <cylinder>
            <radius>0.033000</radius>
            <length>0.023000</length>
          </cylinder>
        </geometry>
      </visual>
    </link>

    <joint name="left_wheel" type="revolute">
      <parent>base_footprint</parent>
      <child>left_wheel</child>
      <axis>
        <xyz>0 1 0</xyz>
      </axis>
    </joint>

    <joint name="right_wheel" type="revolute">
      <parent>base_footprint</parent>
      <child>right_wheel</child>
      <axis>
        <xyz>0 1 0</xyz>
      </axis>
    </joint>

    <plugin name="differential_drive_controller" filename="libgazebo_ros_diff_drive.so">
      <alwaysOn>true</alwaysOn>
      <!--<updateRate>${update_rate}</updateRate>-->
      <leftJoint>right_wheel</leftJoint>
      <rightJoint>left_wheel</rightJoint>
      <wheelSeparation>0.26</wheelSeparation>
      <wheelDiameter>0.066</wheelDiameter>
      <torque>20</torque>
      <commandTopic>cmd_vel</commandTopic>
      <odometryTopic>odom</odometryTopic>
      <odometryFrame>odom</odometryFrame>
      <robotBaseFrame>base_footprint</robotBaseFrame>
      <!--addes-->
      <publishWheelTF>true</publishWheelTF>
      <publishOdomTF>true</publishOdomTF>
      <publishWheelJointState>true</publishWheelJointState>
      <wheelAcceleration>0</wheelAcceleration>
      <wheelTorque>5</wheelTorque>
      <updateRate>100</updateRate>
<!--      <odometrySource>1</odometrySource>-->
      <publishTf>1</publishTf>

    </plugin>
  </model>
</sdf>
