<?xml version="1.0" ?>
<!-- =================================================================================== -->
<!-- |    This document was autogenerated by xacro from iRobot.urdf.xacro              | -->
<!-- |    EDITING THIS FILE BY HAND IS NOT RECOMMENDED                                 | -->
<!-- =================================================================================== -->
<robot name="iRobot">

    <material name="black"> 
        <color rgba="0 0 0 1"/>
    </material>
    <material name="blue"> 
        <color rgba="0.0 0.0 0.8 1"/>
    </material>
      <material name="red">
    <color rgba="0.8 0.0 0.0 1"/>
  </material>
<material name="grey">
    <color rgba="0.4 0.4 0.4 1.0"/>
  </material>
  <material name="body">
    <texture filename="materials/textures/create_body.png"/>
</material>


    <link name="base_footprint">
        <visual name="base_visual">
            <origin xyz="0 0 0.047800" rpy="0 0 0 " />
            <geometry>
                <mesh filename="meshes/create_body.dae"/>
            </geometry>
            <material name="grey"/>

        </visual>
        <collision name="base_visual">
            <origin xyz="0 0 0.047800" rpy="0 0 0 " />
            <geometry>
                <mesh filename="meshes/create_body.dae"/>
            </geometry>
        </collision>
    </link>
    <link name="us1_link"/>
    <link name="us2_link"/>
    <link name="us3_link"/>
    <link name="us4_link"/>
    <link name="us5_link"/>
    <link name="us6_link"/>
    <link name="us7_link"/>
    <link name="us8_link"/>
    <link name="imu_link"/>

    <!-- Left  Wheel -->
    <link name="left_wheel_link">
        <visual>
            <geometry>
                <cylinder length="0.023000" radius="0.033000"/>
            </geometry>
            <material name="blue"/>
        </visual>
        <collision>
            <geometry>
                <cylinder length="0.023000" radius="0.033000"/>
            </geometry>
        </collision>
    </link>

    <!-- Right  Wheel -->
    <link name="right_wheel_link">
        <visual>
            <geometry>
                <cylinder length="0.023000" radius="0.033000"/>
            </geometry>
            <material name="red"/>
        </visual>
        <collision>
            <geometry>
                <cylinder length="0.023000" radius="0.033000"/>
            </geometry>
        </collision>
    </link>

    <link name="front_wheel_link">
        <visual>
            <geometry>
                <sphere radius="0.018000" />
            </geometry>
            <material name="black"/>
        </visual>
        <collision>
            <geometry>
                <sphere radius="0.018000" />
            </geometry>
        </collision>
    </link>

    <link name="rear_wheel_link">
        <visual>
            <geometry>
                <sphere radius="0.015000" />
            </geometry>
            <material name="black"/>
        </visual>
        <collision>
            <geometry>
                <sphere radius="0.015000" />
            </geometry>
        </collision>
    </link>
  <link name="laser">
    <inertial>
      <origin rpy="0 0 0" xyz="0 0 0"/>
      <mass value="0.130"/>
      <inertia ixx="4E-06" ixy="0" ixz="0" iyy="4E-06" iyz="0" izz="4E-06"/>
    </inertial>
    <collision>
      <origin rpy="0 0 0" xyz="0 0 0"/>
      <geometry>
        <box size="0.1 0.1 0.1"/>
      </geometry>
    </collision>
    <visual>
      <origin rpy="0 0 0" xyz="0 0 0"/>
      <geometry>
        <mesh filename="meshes/hokuyo.obj"/>
        <material name="grey"/>
      </geometry>
    </visual>
  </link>

  <joint name="hokuyo_joint" type="fixed">
    <origin rpy="0 0 0" xyz="-0.08 0.0 0.085"/>
    <parent link="base_footprint"/>
    <child link="laser"/>
    <axis xyz="0 0 1"/>
  </joint>

    <joint name="base_us1_joint" type="fixed">
        <parent link="base_footprint"/>
        <child link="us1_link"/>
        <origin xyz="0.13 0.11 0.07" rpy="0 0 1.5708" />
    </joint>

    <joint name="base_us2_joint" type="fixed">
        <parent link="base_footprint"/>
        <child link="us2_link"/>
        <origin xyz="0.11 0.13 0.07" rpy="0 0 0" />
    </joint>

    <joint name="base_us3_joint" type="fixed">
        <parent link="base_footprint"/>
        <child link="us3_link"/>
        <origin xyz="0.11 -0.13 0.07" rpy="0 0 0" />
    </joint>

    <joint name="base_us4_joint" type="fixed">
        <parent link="base_footprint"/>
        <child link="us4_link"/>
        <origin xyz="0.13 -0.11 0.07" rpy="0 0 -1.5708" />
    </joint>

    <joint name="base_us5_joint" type="fixed">
        <parent link="base_footprint"/>
        <child link="us5_link"/>
        <origin xyz="-0.13 -0.11 0.07" rpy="0 0 -1.5708" />
    </joint>
    <joint name="base_us6_joint" type="fixed">
        <parent link="base_footprint"/>
        <child link="us6_link"/>
        <origin xyz="-0.11 -0.13 0.07" rpy="0 0 3.14" />
    </joint>
    <joint name="base_us7_joint" type="fixed">
        <parent link="base_footprint"/>
        <child link="us7_link"/>
        <origin xyz="-0.11 0.13 0.07" rpy="0 0 3.14" />
    </joint>
    <joint name="base_us8_joint" type="fixed">
        <parent link="base_footprint"/>
        <child link="us8_link"/>
        <origin xyz="-0.13 0.11 0.07" rpy="0 0 1.5708" />
    </joint>
    <joint name="base_imu_joint" type="fixed">
        <parent link="base_footprint"/>
        <child link="imu_link"/>
        <origin xyz="0 0 0" rpy="0 0 0" />
    </joint>

    <joint name="left_wheel" type="continuous">
        <parent link="base_footprint"/>
        <child link="left_wheel_link"/>
        <origin xyz="0 0.130000 0.032000" rpy="0 1.5708 1.5708" />
        <axis xyz="0 0 1"/>
    </joint>

    <joint name="right_wheel" type="continuous">
        <parent link="base_footprint"/>
        <child link="right_wheel_link"/>
        <origin xyz="0 -0.130000 0.032000" rpy="0 1.5708 1.5708" />
        <axis xyz="0 0 1"/>
    </joint>

    <joint name="front_wheel" type="fixed">
        <parent link="base_footprint"/>
        <child link="front_wheel_link"/>
        <origin xyz="0.130000 0 0.017000" rpy="0 1.5708 1.5708" />
        <axis xyz="0 0 1"/>
    </joint>

        <joint name="rear_wheel" type="fixed">
        <parent link="base_footprint"/>
        <child link="rear_wheel_link"/>
        <origin xyz="-0.130000 0 0.017000" rpy="0 1.5708 1.5708" />
        <axis xyz="0 0 1"/>
    </joint>

</robot>
